<?xml version="1.0" ?>
<robot name="base" xmlns:xacro="http://www.ros.org/wiki/xacro">

<xacro:include filename="$(find base_description)/urdf/materials.xacro" />
<xacro:include filename="$(find base_description)/urdf/base.trans" />
<xacro:include filename="$(find base_description)/urdf/base.gazebo" />
<link name="base_link">
  <inertial>
    <origin xyz="-0.010929449941574321 -8.969555028301508e-16 0.07607552560113368" rpy="0 0 0"/>
    <mass value="2.5850061422858865"/>
    <inertia ixx="0.00307" iyy="0.011276" izz="0.012817" ixy="0.0" iyz="-0.0" ixz="-0.00059"/>
  </inertial>
  <visual>
    <origin xyz="0 0 0" rpy="0 0 0"/>
    <geometry>
      <mesh filename="package://base_description/meshes/base_link.stl" scale="0.001 0.001 0.001"/>
    </geometry>
    <material name="silver"/>
  </visual>
  <collision>
    <origin xyz="0 0 0" rpy="0 0 0"/>
    <geometry>
      <mesh filename="package://base_description/meshes/base_link.stl" scale="0.001 0.001 0.001"/>
    </geometry>
  </collision>
</link>

<link name="right_wheel_1">
  <inertial>
    <origin xyz="1.4440120647829513e-07 -0.007500000000000472 4.469152517574959e-07" rpy="0 0 0"/>
    <mass value="0.9248063374004952"/>
    <inertia ixx="0.000595" iyy="0.001156" izz="0.000595" ixy="0.0" iyz="-0.0" ixz="0.0"/>
  </inertial>
  <visual>
    <origin xyz="0.081161 0.055 -0.050915" rpy="0 0 0"/>
    <geometry>
      <mesh filename="package://base_description/meshes/right_wheel_1.stl" scale="0.001 0.001 0.001"/>
    </geometry>
    <material name="silver"/>
  </visual>
  <collision>
    <origin xyz="0.081161 0.055 -0.050915" rpy="0 0 0"/>
    <geometry>
      <mesh filename="package://base_description/meshes/right_wheel_1.stl" scale="0.001 0.001 0.001"/>
    </geometry>
  </collision>
</link>

<link name="left_wheel_1">
  <inertial>
    <origin xyz="1.444012065199285e-07 0.00749999999999882 4.469152517574959e-07" rpy="0 0 0"/>
    <mass value="0.9248063374004952"/>
    <inertia ixx="0.000595" iyy="0.001156" izz="0.000595" ixy="0.0" iyz="-0.0" ixz="0.0"/>
  </inertial>
  <visual>
    <origin xyz="0.081161 -0.055 -0.050915" rpy="0 0 0"/>
    <geometry>
      <mesh filename="package://base_description/meshes/left_wheel_1.stl" scale="0.001 0.001 0.001"/>
    </geometry>
    <material name="silver"/>
  </visual>
  <collision>
    <origin xyz="0.081161 -0.055 -0.050915" rpy="0 0 0"/>
    <geometry>
      <mesh filename="package://base_description/meshes/left_wheel_1.stl" scale="0.001 0.001 0.001"/>
    </geometry>
  </collision>
</link>

<link name="lidar_1">
  <inertial>
    <origin xyz="1.4440120737341244e-07 -9.418203707748374e-16 0.015000446915251375" rpy="0 0 0"/>
    <mass value="0.2959380279681584"/>
    <inertia ixx="5.2e-05" iyy="5.2e-05" izz="5.9e-05" ixy="0.0" iyz="-0.0" ixz="0.0"/>
  </inertial>
  <visual>
    <origin xyz="-0.053839 0.0 -0.105915" rpy="0 0 0"/>
    <geometry>
      <mesh filename="package://base_description/meshes/lidar_1.stl" scale="0.001 0.001 0.001"/>
    </geometry>
    <material name="silver"/>
  </visual>
  <collision>
    <origin xyz="-0.053839 0.0 -0.105915" rpy="0 0 0"/>
    <geometry>
      <mesh filename="package://base_description/meshes/lidar_1.stl" scale="0.001 0.001 0.001"/>
    </geometry>
  </collision>
</link>

<joint name="Rev1" type="continuous">
  <origin xyz="-0.081161 -0.055 0.050915" rpy="0 0 0"/>
  <parent link="base_link"/>
  <child link="right_wheel_1"/>
  <axis xyz="-0.0 -1.0 -0.0"/>
</joint>

<joint name="Rev2" type="continuous">
  <origin xyz="-0.081161 0.055 0.050915" rpy="0 0 0"/>
  <parent link="base_link"/>
  <child link="left_wheel_1"/>
  <axis xyz="0.0 1.0 0.0"/>
</joint>

<joint name="Rev3" type="continuous">
  <origin xyz="0.053839 0.0 0.105915" rpy="0 0 0"/>
  <parent link="base_link"/>
  <child link="lidar_1"/>
  <axis xyz="0.0 -0.0 1.0"/>
</joint>

</robot>
